Traceback (most recent call last):
  File "<pyshell#387>", line 2, in <module>
Exception: This is the error message
Traceback (most recent call last):
  File "<pyshell#401>", line 2, in <module>
Exception: This is the error message
